Workbook

Sheet 3.5mil_ac
A1: 3.5 million acre scenario: highest wildfire hazard potential, most accessible (A1) biomass | K1: Accessibility classifications key
A2: Counties: A2:A57, fraction of A58 | K2: A1: 0-500 ft from road, <20% slope
A3: Fraction of A58 (Tehama County, CA) | K3: A2: 500-1,000 ft from road, <20% slope
A4: Total ac w/o A58: | B4: =SUM(all_data!K2:'all_data'!K57) -> 3397546.8 | K4: A3: 1,000 ft - 0.5 mi from road, <20% slope
A5: Total ac w/ A58: | B5: =SUM(all_data!K2:'all_data'!K58) -> 3950945.2 | K5: A4: 0-500 ft from road, 20-40% slope
A6: Ac over 3.5 mil: | B6: =B5-3500000 -> 450945.2 | K6: A5: 500-1,000 ft from road, 20-40% slope
A7: Total A58: | B7: =all_data!K58 -> 553398.4 | K7: A6: 1,000 ft - 0.5 mi from road, 20-40% slope
A8: Amount from A58: | B8: =B7-B6 -> 102453.2
A9: Fraction of A58: | B9: =B8/B7 -> 0.18513462
A11: Results
A12: total BDMT | B12: =SUM(all_data!AC2:'all_data'!AC57, all_data!AC58*'3.5mil_ac'!B9)*0.907185 -> 42603357
A13: total initial MTCO2e | B13: =B12*0.5*3.67 -> 78177159
A14: forestry net income | B14: =SUM(all_data!DQ2:'all_data'!DQ57, all_data!DQ58*'3.5mil_ac'!B9) -> -1.3423018e+09
A15: pile burn net income | B15: =SUM(all_data!CR2:'all_data'!CR57, all_data!CR58*'3.5mil_ac'!B9) -> -3.1333406e+09
A16: burial net income | B16: =SUM(all_data!BP2:'all_data'!BP57, all_data!BP58*'3.5mil_ac'!B9) -> 2.0031258e+09
A17: burial mean eta | B17: =AVERAGE(all_data!F2:'all_data'!F57, all_data!F58*'3.5mil_ac'!B9) -> 0.77183891
A18: burial MTCO2e stored | B18: =SUM(c_stored!K2:'c_stored'!K57, c_stored!K58*'3.5mil_ac'!B9) -> 60723475
A19: beccs net income | B19: =SUM(all_data!EP2:'all_data'!EP57, all_data!EP58*'3.5mil_ac'!B9) -> 2.0724276e+09
A20: beccs mean eta | B20: =AVERAGE(all_data!H2:'all_data'!H57, all_data!H58*'3.5mil_ac'!B9) -> 0.80149886
A21: beccs MTCO2e stored | B21: =SUM(c_stored!AD2:'c_stored'!AD57, c_stored!AD58*'3.5mil_ac'!B9) -> 63582685
A22: biochar net income | B22: =SUM(all_data!FO2:'all_data'!FO57, all_data!FO58*'3.5mil_ac'!B9) -> 7.8273161e+08

Sheet all_data
A1: start_state | B1: county_biomass | C1: index | D1: wildfire_hazard_potential | E1: bur_path_length_km | F1: bur_w2_c_eff | G1: beccs_90_path_length_km | H1: beccs_90_w2_c_eff | I1: USFS_Acre_A1 | J1: Other_Acre_A1 | K1: total_acre_A1 | L1: USFS_Acre_A2 | M1: Other_Acre_A2 | N1: total_acre_A2 | O1: USFS_Acre_A3 | P1: Other_Acre_A3 | Q1: total_acre_A3 | R1: USFS_Acre_A4 | S1: Other_Acre_A4 | T1: total_acre_A4 | U1: USFS_Acre_A5 | V1: Other_Acre_A5 | W1: total_acre_A5 | X1: USFS_Acre_A6 | Y1: Other_Acre_A6 | Z1: total_acre_A6 | AA1: USFS_BDT_A1 | AB1: Other_BDT_A1 | AC1: Total_BDT_A1 | AD1: USFS_BDT_A2 | AE1: Other_BDT_A2 | AF1: Total_BDT_A2 | AG1: USFS_BDT_A3 | AH1: Other_BDT_A3 | AI1: Total_BDT_A3 | AJ1: USFS_BDT_A4 | AK1: Other_BDT_A4 | AL1: Total_BDT_A4 | AM1: USFS_BDT_A5 | AN1: Other_BDT_A5 | AO1: Total_BDT_A5 | AP1: USFS_BDT_A6 | AQ1: Other_BDT_A6 | AR1: Total_BDT_A6 | AS1: Total_BDT | AT1: USFS_co2i_A1 | AU1: Other_co2i_A1 | AV1: Total_co2i_A1 | AW1: USFS_co2i_A2 | AX1: Other_co2i_A2 | AY1: Total_co2i_A2 | AZ1: USFS_co2i_A3 | BA1: Other_co2i_A3 | BB1: Total_co2i_A3 | BC1: USFS_co2i_A4 | BD1: Other_co2i_A4 | BE1: Total_co2i_A4 | BF1: USFS_co2i_A5 | BG1: Other_co2i_A5 | BH1: Total_co2i_A5 | BI1: USFS_co2i_A6 | BJ1: Other_co2i_A6 | BK1: Total_co2i_A6 | BL1: Total_co2i | BM1: ni_bur_A1/MTCO2e | BN1: USFS_ni_A1 | BO1: Other_ni_A1 | BP1: Total_ni_A1 | BQ1: ni_bur_A2/MTCO2e | BR1: USFS_ni_A2 | BS1: Other_ni_A2 | BT1: Total_ni_A2 | BU1: ni_bur_A3/MTCO2e | BV1: USFS_ni_A3 | BW1: Other_ni_A3 | BX1: Total_ni_A3 | BY1: ni_bur_A4/MTCO2e | BZ1: USFS_ni_A4 | CA1: Other_ni_A4 | CB1: Total_ni_A4 | CC1: ni_bur_A5/MTCO2e | CD1: USFS_ni_A5 | CE1: Other_ni_A5 | CF1: Total_ni_A5 | CG1: ni_bur_A6/MTCO2e | CH1: USFS_ni_A6 | CI1: Other_ni_A6 | CJ1: Total_ni_A6 | CK1: Total_ni_burial | CL1: pile_burn_breakeven_rho_b | CM1: pile_burn_breakeven_rho_l | CN1: pile_burn_breakeven_rho_h | CO1: ni_pb_A1/MTCO2e | CP1: USFS_ni_A1 | CQ1: Other_ni_A1 | CR1: Total_ni_A1 | CS1: ni_pb_A2/MTCO2e | CT1: USFS_ni_A2 | CU1: Other_ni_A2 | CV1: Total_ni_A2 | CW1: ni_pb_A3/MTCO2e | CX1: USFS_ni_A3 | CY1: Other_ni_A3 | CZ1: Total_ni_A3 | DA1: ni_pb_A4/MTCO2e | DB1: USFS_ni_A4 | DC1: Other_ni_A4 | DD1: Total_ni_A4 | DE1: ni_pb_A5/MTCO2e | DF1: USFS_ni_A5 | DG1: Other_ni_A5 | DH1: Total_ni_A5 | DI1: ni_pb_A6/MTCO2e | DJ1: USFS_ni_A6 | DK1: Other_ni_A6 | DL1: Total_ni_A6 | DM1: Total_ni_pile_burn | DN1: ni_f_A1/MTCO2e | DO1: USFS_ni_A1 | DP1: Other_ni_A1 | DQ1: Total_ni_A1 | DR1: ni_f_A2/MTCO2e | DS1: USFS_ni_A2 | DT1: Other_ni_A2 | DU1: Total_ni_A2 | DV1: ni_f_A3/MTCO2e | DW1: USFS_ni_A3 | DX1: Other_ni_A3 | DY1: Total_ni_A3 | DZ1: ni_f_A4/MTCO2e | EA1: USFS_ni_A4 | EB1: Other_ni_A4 | EC1: Total_ni_A4 | ED1: ni_f_A5/MTCO2e | EE1: USFS_ni_A5 | EF1: Other_ni_A5 | EG1: Total_ni_A5 | EH1: ni_f_A6/MTCO2e | EI1: USFS_ni_A6 | EJ1: Other_ni_A6 | EK1: Total_ni_A6 | EL1: Total_ni_forestry_only | EM1: ni_bec_A1/MTCO2e | EN1: USFS_ni_A1 | EO1: Other_ni_A1 | EP1: Total_ni_A1 | EQ1: ni_bec_A2/MTCO2e | ER1: USFS_ni_A2 | ES1: Other_ni_A2 | ET1: Total_ni_A2 | EU1: ni_bec_A3/MTCO2e | EV1: USFS_ni_A3 | EW1: Other_ni_A3 | EX1: Total_ni_A3 | EY1: ni_bec_A4/MTCO2e | EZ1: USFS_ni_A4 | FA1: Other_ni_A4 | FB1: Total_ni_A4 | FC1: ni_bec_A5/MTCO2e | FD1: USFS_ni_A5 | FE1: Other_ni_A5 | FF1: Total_ni_A5 | FG1: ni_bec_A6/MTCO2e | FH1: USFS_ni_A6 | FI1: Other_ni_A6 | FJ1: Total_ni_A6 | FK1: Total_ni_beccs | FL1: ni_char_A1/MTCO2e | FM1: USFS_ni_A1 | FN1: Other_ni_A1 | FO1: Total_ni_A1 | FP1: ni_char_A2/MTCO2e | FQ1: USFS_ni_A2 | FR1: Other_ni_A2 | FS1: Total_ni_A2 | FT1: ni_char_A3/MTCO2e | FU1: USFS_ni_A3 | FV1: Other_ni_A3 | FW1: Total_ni_A3 | FX1: ni_char_A4/MTCO2e | FY1: USFS_ni_A4 | FZ1: Other_ni_A4 | GA1: Total_ni_A4 | GB1: ni_char_A5/MTCO2e | GC1: USFS_ni_A5 | GD1: Other_ni_A5 | GE1: Total_ni_A5 | GF1: ni_char_A6/MTCO2e | GG1: USFS_ni_A6 | GH1: Other_ni_A6 | GI1: Total_ni_A6 | GJ1: Total_ni_char
A2: Nevada | B2: Elko | C2: 51 | D2: 1 | E2: 168.9173 | F2: 0.78545938 | G2: 303.45157 | H2: 0.80084971 | I2: 11927.8 | J2: 14391.7 | K2: =IF(J2<>-999, I2+J2, I2) -> 26319.5 | L2: 1335.9 | M2: 1611.9 | N2: =IF(M2<>-999, L2+M2, L2) -> 2947.8 | O2: 11529.3 | P2: 13910.9 | Q2: =IF(P2<>-999, O2+P2, O2) -> 25440.2 | R2: 20648.1 | S2: 24913.4 | T2: =IF(S2<>-999, R2+S2, R2) -> 45561.5 | U2: 2312.6 | V2: 2790.4 | W2: =IF(V2<>-999, U2+V2, U2) -> 5103 | X2: 19958.4 | Y2: 24081.2 | Z2: =IF(Y2<>-999, X2+Y2, X2) -> 44039.6 | AA2: 91898.7 | AB2: 71834.4 | AC2: 163733.2 | AD2: 10292.9 | AE2: 8045.6 | AF2: 18338.5 | AG2: 88828.8 | AH2: 69434.8 | AI2: 158263.6 | AJ2: 159085.9 | AK2: 124352.5 | AL2: 283438.4 | AM2: 17818 | AN2: 13927.8 | AO2: 31745.8 | AP2: 153771.6 | AQ2: 120198.5 | AR2: 273970.1 | AS2: 929489.67 | AT2: =IF(AA2<>-999,AA2*0.5*3.67*0.907185, -999) -> 152982.34 | AU2: =IF(AB2<>-999,AB2*0.5*3.67*0.907185, -999) -> 119581.61 | AV2: =IF(AC2<>-999,AC2*0.5*3.67*0.907185, -999) -> 272564.12 | AW2: =IF(AD2<>-999,AD2*0.5*3.67*0.907185, -999) -> 17134.431 | AX2: =IF(AE2<>-999,AE2*0.5*3.67*0.907185, -999) -> 13393.385 | AY2: =IF(AF2<>-999,AF2*0.5*3.67*0.907185, -999) -> 30527.816 | AZ2: =IF(AG2<>-999,AG2*0.5*3.67*0.907185, -999) -> 147871.92 | BA2: =IF(AH2<>-999,AH2*0.5*3.67*0.907185, -999) -> 115587.03 | ... BL2: =IF(AS2<>-999,AS2*0.5*3.67*0.907185, -999) -> 1547307 | BM2: =-17.17-(0.1023*E2)+F2*(100-8.576-13.681) -> 26.613729 | BN2: =IF(AT2<>-999,AT2*$BM2, -999) -> 4071430.5 | BO2: =IF(AU2<>-999,AU2*$BM2, -999) -> 3182512.6 | BP2: =IF(AV2<>-999,AV2*$BM2, -999) -> 7253947.5 | BQ2: =-19.943-(0.1023*E2)+F2*(100-8.576-13.681) -> 23.840729 | BR2: =IF(AW2<>-999,AW2*$BQ2, -999) -> 408497.32 | BS2: =IF(AX2<>-999,AX2*$BQ2, -999) -> 319308.07 | BT2: =IF(AY2<>-999,AY2*$BQ2, -999) -> 727805.39 | BU2: =-25.871-(0.1023*E2)+F2*(100-8.576-13.681) -> 17.912729 | BV2: =IF(AZ2<>-999,AZ2*$BU2, -999) -> 2648789.7 | BW2: =IF(BA2<>-999,BA2*$BU2, -999) -> 2070479.2 | BX2: =IF(BB2<>-999,BB2*$BU2, -999) -> 4719268.9 | BY2: =-25.245-(0.1023*E2)+F2*(100-8.576-13.681) -> 18.538729 | BZ2: =IF(BC2<>-999,BC2*$BY2, -999) -> 4909571.3 | CA2: =IF(BD2<>-999,BD2*$BY2, -999) -> 3837659.2 | CB2: =IF(BE2<>-999,BE2*$BY2, -999) -> 8747230.5 | CC2: =-29.317-(0.1023*E2)+F2*(100-8.576-13.681) -> 14.466729 | CD2: =IF(BF2<>-999,BF2*$CC2, -999) -> 429102.68 | CE2: =IF(BG2<>-999,BG2*$CC2, -999) -> 335416.79 | CF2: =IF(BH2<>-999,BH2*$CC2, -999) -> 764519.46 | CG2: =-38.03-(0.1023*E2)+F2*(100-8.576-13.681) -> 5.7537289 | CH2: =IF(BI2<>-999,BI2*$CG2, -999) -> 1472846.4 | CI2: =IF(BJ2<>-999,BJ2*$CG2, -999) -> 1151278.4 | CJ2: =IF(BK2<>-999,BK2*$CG2, -999) -> 2624124.8 | CK2: =BP2+BT2+BX2+CB2+CF2+CJ2 -> 24836897 | CL2: =((-55.825+0.1023*$E2)/$F2)+8.576+13.681 -> -26.815888 | CM2: =((-10.38+0.1023*$E2)/$F2)+8.576+13.681 -> 31.041973 | CN2: =((-100.485+0.1023*$E2)/$F2)+8.576+13.681 -> -83.674335 | CO2: =-17.17-22.91 -> -40.08 | CP2: =IF(AT2<>-999,AT2*$CO2, -999) -> -6131532.2 | CQ2: =IF(AU2<>-999,AU2*$CO2, -999) -> -4792830.9 | CR2: =IF(AV2<>-999,AV2*$CO2, -999) -> -10924370 | CS2: =-19.943-22.91 -> -42.853 | CT2: =IF(AW2<>-999,AW2*$CS2, -999) -> -734261.76 | CU2: =IF(AX2<>-999,AX2*$CS2, -999) -> -573946.75 | CV2: =IF(AY2<>-999,AY2*$CS2, -999) -> -1308208.5 | CW2: =-25.871-22.91 -> -48.781 | CX2: =IF(AZ2<>-999,AZ2*$CO2, -999) -> -5926706.7 | CY2: =IF(BA2<>-999,BA2*$CO2, -999) -> -4632728.3 | CZ2: =IF(BB2<>-999,BB2*$CO2, -999) -> -10559435 | DA2: =-25.245-22.91 -> -48.155 | DB2: =IF(BC2<>-999,BC2*$DA2, -999) -> -12752784 | DC2: =IF(BD2<>-999,BD2*$DA2, -999) -> -9968454.6 | DD2: =IF(BE2<>-999,BE2*$DA2, -999) -> -22721239 | DE2: =-29.317-22.91 -> -52.227 | DF2: =IF(BF2<>-999,BF2*$DE2, -999) -> -1549123.2 | DG2: =IF(BG2<>-999,BG2*$DE2, -999) -> -1210903.5 | DH2: =IF(BH2<>-999,BH2*$DE2, -999) -> -2760026.7 | DI2: =-38.03-22.91 -> -60.94 | DJ2: =IF(BI2<>-999,BI2*$DI2, -999) -> -15599494 | DK2: =IF(BJ2<>-999,BJ2*$DI2, -999) -> -12193642 | DL2: =IF(BK2<>-999,BK2*$DI2, -999) -> -27793136 | DM2: =CR2+CV2+CZ2+DD2+DH2+DL2 -> -76066414 | DN2: =-17.17 -> -17.17 | DO2: =IF(AT2<>-999,AT2*$DN2, -999) -> -2626706.8 | DP2: =IF(AU2<>-999,AU2*$DN2, -999) -> -2053216.3 | DQ2: =IF(AV2<>-999,AV2*$DN2, -999) -> -4679925.9 | DR2: =-19.943 -> -19.943 | DS2: =IF(AW2<>-999,AW2*$DR2, -999) -> -341711.95 | DT2: =IF(AX2<>-999,AX2*$DR2, -999) -> -267104.29 | DU2: =IF(AY2<>-999,AY2*$DR2, -999) -> -608816.24 | DV2: =-25.871 -> -25.871 | DW2: =IF(AZ2<>-999,AZ2*$DV2, -999) -> -3825594.6 | DX2: =IF(BA2<>-999,BA2*$DV2, -999) -> -2990352.1 | DY2: =IF(BB2<>-999,BB2*$DV2, -999) -> -6815946.7 | DZ2: =-25.245 -> -25.245 | EA2: =IF(BC2<>-999, BC2*$DZ2, -999) -> -6685578.5 | EB2: =IF(BD2<>-999, BD2*$DZ2, -999) -> -5225908.8 | EC2: =IF(BE2<>-999, BE2*$DZ2, -999) -> -11911487 | ED2: =-29.317 -> -29.317 | EE2: =IF(BF2<>-999,BF2*$ED2, -999) -> -869581.74 | EF2: =IF(BG2<>-999,BG2*$ED2, -999) -> -679726.15 | EG2: =IF(BH2<>-999,BH2*$ED2, -999) -> -1549307.9 | EH2: =-38.03 -> -38.03 | EI2: =IF(BI2<>-999,BI2*$EH2, -999) -> -9734964.9 | EJ2: =IF(BJ2<>-999,BJ2*$EH2, -999) -> -7609520.7 | EK2: =IF(BK2<>-999,BK2*$EH2, -999) -> -17344486 | EL2: =DQ2+DU2+DY2+EC2+EG2+EK2 -> -42909970 | EM2: =-17.17-(0.1023*G2)+H2*(100+102.093-66.644-64.243) -> 8.8122089 | EN2: =IF(AT2<>-999,AT2*$EM2, -999) -> 1348112.3 | EO2: =IF(AU2<>-999,AU2*$EM2, -999) -> 1053778.1 | EP2: =IF(AV2<>-999,AV2*$EM2, -999) -> 2401891.9 | EQ2: =-19.943-(0.1023*G2)+H2*(100+102.093-66.644-64.243) -> 6.0392089 | ER2: =IF(AW2<>-999,AW2*$EQ2, -999) -> 103478.41 | ES2: =IF(AX2<>-999,AX2*$EQ2, -999) -> 80885.452 | ET2: =IF(AY2<>-999,AY2*$EQ2, -999) -> 184363.86 | EU2: =-25.871-(0.1023*G2)+H2*(100+102.093-66.644-64.243) -> 0.1112089 | EV2: =IF(AZ2<>-999,AZ2*$EU2, -999) -> 16444.674 | EW2: =IF(BA2<>-999,BA2*$EU2, -999) -> 12854.307 | EX2: =IF(BB2<>-999,BB2*$EU2, -999) -> 29298.982 | EY2: =-25.245-(0.1023*G2)+H2*(100+102.093-66.644-64.243) -> 0.7372089 | EZ2: =IF(BC2<>-999, BC2*$EY2, -999) -> 195233.43 | FA2: =IF(BD2<>-999, BD2*$EY2, -999) -> 152607.9 | FB2: =IF(BE2<>-999, BE2*$EY2, -999) -> 347841.33 | FC2: =-29.317-(0.1023*G2)+H2*(100+102.093-66.644-64.243) -> -3.3347911 | FD2: =IF(BF2<>-999,BF2*$FC2, -999) -> -98914.399 | FE2: =IF(BG2<>-999,BG2*$FC2, -999) -> -77318.44 | FF2: =IF(BH2<>-999,BH2*$FC2, -999) -> -176232.84 | FG2: =-38.03-(0.1023*G2)+H2*(100+102.093-66.644-64.243) -> -12.047791 | FH2: =IF(BI2<>-999,BI2*$FG2, -999) -> -3084008 | FI2: =IF(BJ2<>-999,BJ2*$FG2, -999) -> -2410673.6 | FJ2: =IF(BK2<>-999,BK2*$FG2, -999) -> -5494681.5 | FK2: =EP2+ET2+EX2+FB2+FF2+FJ2 -> -2707518.3 | FL2: =-17.17+0.435*(100+83.36-27.092-93.78) -> 10.01228 | FM2: =IF(AT2<>-999,AT2*$FL2, -999) -> 1531702 | FN2: =IF(AU2<>-999,AU2*$FL2, -999) -> 1197284.6 | FO2: =IF(AV2<>-999,AV2*$FL2, -999) -> 2728988.2 | FP2: =-19.943+0.435*(100+83.36-27.092-93.78) -> 7.23928 | FQ2: =IF(AW2<>-999,AW2*$FP2, -999) -> 124040.94 | FR2: =IF(AX2<>-999,AX2*$FP2, -999) -> 96958.467 | FS2: =IF(AY2<>-999,AY2*$FP2, -999) -> 220999.41 | FT2: =-25.871+0.435*(100+83.36-27.092-93.78) -> 1.31128 | FU2: =IF(AZ2<>-999,AZ2*$FT2, -999) -> 193901.5 | FV2: =IF(BA2<>-999,BA2*$FT2, -999) -> 151566.97 | FW2: =IF(BB2<>-999,BB2*$FT2, -999) -> 345468.46 | FX2: =-25.245+0.435*(100+83.36-27.092-93.78) -> 1.93728 | FY2: =IF(BC2<>-999, BC2*$FX2, -999) -> 513045.65 | FZ2: =IF(BD2<>-999, BD2*$FX2, -999) -> 401031.83 | GA2: =IF(BE2<>-999, BE2*$FX2, -999) -> 914077.49 | GB2: =-29.317+0.435*(100+83.36-27.092-93.78) -> -2.13472 | GC2: =IF(BF2<>-999,BF2*$GB2, -999) -> -63318.673 | GD2: =IF(BG2<>-999,BG2*$GB2, -999) -> -49494.321 | GE2: =IF(BH2<>-999,BH2*$GB2, -999) -> -112812.99 | GF2: =-38.03+0.435*(100+83.36-27.092-93.78) -> -10.84772 | GG2: =IF(BI2<>-999,BI2*$GF2, -999) -> -2776812.3 | GH2: =IF(BJ2<>-999,BJ2*$GF2, -999) -> -2170548.2 | GI2: =IF(BK2<>-999,BK2*$GF2, -999) -> -4947360.6 | GJ2: =FO2+FS2+FW2+GA2+GE2+GI2 -> -850639.97
A3: California | B3: Mariposa | C3: 125 | D3: 0.996 | E3: 268.86479 | F3: 0.77833747 | G3: 69.855029 | H3: 0.81849499 | I3: 205307.2 | J3: 50284.8 | K3: =IF(J3<>-999, I3+J3, I3) -> 255592 | L3: 102281 | M3: 25051.2 | N3: =IF(M3<>-999, L3+M3, L3) -> 127332.2 | O3: 177452.4 | P3: 43462.5 | Q3: =IF(P3<>-999, O3+P3, O3) -> 220914.9 | R3: 216090.2 | S3: 52925.9 | T3: =IF(S3<>-999, R3+S3, R3) -> 269016.1 | U3: 107652.9 | V3: 26366.9 | W3: =IF(V3<>-999, U3+V3, U3) -> 134019.8 | X3: 186772.4 | Y3: 45745.2 | Z3: =IF(Y3<>-999, X3+Y3, X3) -> 232517.6 | AA3: 2786631.7 | AB3: 409620.4 | AC3: 3196252.1 | AD3: 1388258.5 | AE3: 204066.8 | AF3: 1592325.3 | AG3: 2408558.9 | AH3: 354045.7 | AI3: 2762604.6 | AJ3: 2932989.4 | AK3: 431134.3 | AL3: 3364123.6 | AM3: 1461171.7 | AN3: 214784.7 | AO3: 1675956.4 | AP3: 2535059.7 | AQ3: 372640.7 | AR3: 2907700.4 | AS3: 15498962 | AT3: =IF(AA3<>-999,AA3*0.5*3.67*0.907185, -999) -> 4638862.5 | AU3: =IF(AB3<>-999,AB3*0.5*3.67*0.907185, -999) -> 681888.72 | AV3: =IF(AC3<>-999,AC3*0.5*3.67*0.907185, -999) -> 5320751.2 | AW3: =IF(AD3<>-999,AD3*0.5*3.67*0.907185, -999) -> 2311012.4 | AX3: =IF(AE3<>-999,AE3*0.5*3.67*0.907185, -999) -> 339706.83 | AY3: =IF(AF3<>-999,AF3*0.5*3.67*0.907185, -999) -> 2650719.2 | AZ3: =IF(AG3<>-999,AG3*0.5*3.67*0.907185, -999) -> 4009490.6 | BA3: =IF(AH3<>-999,AH3*0.5*3.67*0.907185, -999) -> 589374.38 | ... BL3: =IF(AS3<>-999,AS3*0.5*3.67*0.907185, -999) -> 25800882 | BM3: =-17.17-(0.1023*E3)+F3*(100-8.576-13.681) -> 15.835422 | BN3: =IF(AT3<>-999,AT3*$BM3, -999) -> 73458346 | BO3: =IF(AU3<>-999,AU3*$BM3, -999) -> 10797996 | BP3: =IF(AV3<>-999,AV3*$BM3, -999) -> 84256341 | BQ3: =-19.943-(0.1023*E3)+F3*(100-8.576-13.681) -> 13.062422 | BR3: =IF(AW3<>-999,AW3*$BQ3, -999) -> 30187419 | BS3: =IF(AX3<>-999,AX3*$BQ3, -999) -> 4437394 | BT3: =IF(AY3<>-999,AY3*$BQ3, -999) -> 34624813 | BU3: =-25.871-(0.1023*E3)+F3*(100-8.576-13.681) -> 7.134422 | BV3: =IF(AZ3<>-999,AZ3*$BU3, -999) -> 28605398 | BW3: =IF(BA3<>-999,BA3*$BU3, -999) -> 4204845.5 | BX3: =IF(BB3<>-999,BB3*$BU3, -999) -> 32810244 | BY3: =-25.245-(0.1023*E3)+F3*(100-8.576-13.681) -> 7.760422 | BZ3: =IF(BC3<>-999,BC3*$BY3, -999) -> 37890275 | CA3: =IF(BD3<>-999,BD3*$BY3, -999) -> 5569674.9 | CB3: =IF(BE3<>-999,BE3*$BY3, -999) -> 43459949 | CC3: =-29.317-(0.1023*E3)+F3*(100-8.576-13.681) -> 3.688422 | CD3: =IF(BF3<>-999,BF3*$CC3, -999) -> 8971680.2 | CE3: =IF(BG3<>-999,BG3*$CC3, -999) -> 1318790.7 | CF3: =IF(BH3<>-999,BH3*$CC3, -999) -> 10290471 | CG3: =-38.03-(0.1023*E3)+F3*(100-8.576-13.681) -> -5.024578 | CH3: =IF(BI3<>-999,BI3*$CG3, -999) -> -21204094 | CI3: =IF(BJ3<>-999,BJ3*$CG3, -999) -> -3116892.4 | CJ3: =IF(BK3<>-999,BK3*$CG3, -999) -> -24320986 | CK3: =BP3+BT3+BX3+CB3+CF3+CJ3 -> 1.8112083e+08 | CL3: =((-55.825+0.1023*$E3)/$F3)+8.576+13.681 -> -14.128415 | CM3: =((-10.38+0.1023*$E3)/$F3)+8.576+13.681 -> 44.258855 | CN3: =((-100.485+0.1023*$E3)/$F3)+8.576+13.681 -> -71.507125 | CO3: =-17.17-22.91 -> -40.08 | CP3: =IF(AT3<>-999,AT3*$CO3, -999) -> -1.8592561e+08 | CQ3: =IF(AU3<>-999,AU3*$CO3, -999) -> -27330100 | CR3: =IF(AV3<>-999,AV3*$CO3, -999) -> -2.1325571e+08 | CS3: =-19.943-22.91 -> -42.853 | CT3: =IF(AW3<>-999,AW3*$CS3, -999) -> -99033813 | CU3: =IF(AX3<>-999,AX3*$CS3, -999) -> -14557457 | CV3: =IF(AY3<>-999,AY3*$CS3, -999) -> -1.1359127e+08 | CW3: =-25.871-22.91 -> -48.781 | CX3: =IF(AZ3<>-999,AZ3*$CO3, -999) -> -1.6070038e+08 | CY3: =IF(BA3<>-999,BA3*$CO3, -999) -> -23622125 | CZ3: =IF(BB3<>-999,BB3*$CO3, -999) -> -1.8432251e+08 | DA3: =-25.245-22.91 -> -48.155 | DB3: =IF(BC3<>-999,BC3*$DA3, -999) -> -2.3511688e+08 | DC3: =IF(BD3<>-999,BD3*$DA3, -999) -> -34560968 | DD3: =IF(BE3<>-999,BE3*$DA3, -999) -> -2.6967784e+08 | DE3: =-29.317-22.91 -> -52.227 | DF3: =IF(BF3<>-999,BF3*$DE3, -999) -> -1.2703642e+08 | DG3: =IF(BG3<>-999,BG3*$DE3, -999) -> -18673699 | DH3: =IF(BH3<>-999,BH3*$DE3, -999) -> -1.4571012e+08 | DI3: =-38.03-22.91 -> -60.94 | DJ3: =IF(BI3<>-999,BI3*$DI3, -999) -> -2.5717134e+08 | DK3: =IF(BJ3<>-999,BJ3*$DI3, -999) -> -37802861 | DL3: =IF(BK3<>-999,BK3*$DI3, -999) -> -2.949742e+08 | DM3: =CR3+CV3+CZ3+DD3+DH3+DL3 -> -1.2215317e+09 | DN3: =-17.17 -> -17.17 | DO3: =IF(AT3<>-999,AT3*$DN3, -999) -> -79649270 | DP3: =IF(AU3<>-999,AU3*$DN3, -999) -> -11708029 | DQ3: =IF(AV3<>-999,AV3*$DN3, -999) -> -91357299 | DR3: =-19.943 -> -19.943 | DS3: =IF(AW3<>-999,AW3*$DR3, -999) -> -46088520 | DT3: =IF(AX3<>-999,AX3*$DR3, -999) -> -6774773.4 | DU3: =IF(AY3<>-999,AY3*$DR3, -999) -> -52863293 | DV3: =-25.871 -> -25.871 | DW3: =IF(AZ3<>-999,AZ3*$DV3, -999) -> -1.0372953e+08 | DX3: =IF(BA3<>-999,BA3*$DV3, -999) -> -15247705 | DY3: =IF(BB3<>-999,BB3*$DV3, -999) -> -1.1897724e+08 | DZ3: =-25.245 -> -25.245 | EA3: =IF(BC3<>-999, BC3*$DZ3, -999) -> -1.2325876e+08 | EB3: =IF(BD3<>-999, BD3*$DZ3, -999) -> -18118402 | EC3: =IF(BE3<>-999, BE3*$DZ3, -999) -> -1.4137716e+08 | ED3: =-29.317 -> -29.317 | EE3: =IF(BF3<>-999,BF3*$ED3, -999) -> -71310373 | EF3: =IF(BG3<>-999,BG3*$ED3, -999) -> -10482257 | EG3: =IF(BH3<>-999,BH3*$ED3, -999) -> -81792630 | EH3: =-38.03 -> -38.03 | EI3: =IF(BI3<>-999,BI3*$EH3, -999) -> -1.6048943e+08 | EJ3: =IF(BJ3<>-999,BJ3*$EH3, -999) -> -23591119 | EK3: =IF(BK3<>-999,BK3*$EH3, -999) -> -1.8408055e+08 | EL3: =DQ3+DU3+DY3+EC3+EG3+EK3 -> -6.7044817e+08 | EM3: =-17.17-(0.1023*G3)+H3*(100+102.093-66.644-64.243) -> 33.965585 | EN3: =IF(AT3<>-999,AT3*$EM3, -999) -> 1.5756168e+08 | EO3: =IF(AU3<>-999,AU3*$EM3, -999) -> 23160749 | EP3: =IF(AV3<>-999,AV3*$EM3, -999) -> 1.8072243e+08 | EQ3: =-19.943-(0.1023*G3)+H3*(100+102.093-66.644-64.243) -> 31.192585 | ER3: =IF(AW3<>-999,AW3*$EQ3, -999) -> 72086449 | ES3: =IF(AX3<>-999,AX3*$EQ3, -999) -> 10596334 | ET3: =IF(AY3<>-999,AY3*$EQ3, -999) -> 82682784 | EU3: =-25.871-(0.1023*G3)+H3*(100+102.093-66.644-64.243) -> 25.264585 | EV3: =IF(AZ3<>-999,AZ3*$EU3, -999) -> 1.0129812e+08 | EW3: =IF(BA3<>-999,BA3*$EU3, -999) -> 14890299 | EX3: =IF(BB3<>-999,BB3*$EU3, -999) -> 1.1618841e+08 | EY3: =-25.245-(0.1023*G3)+H3*(100+102.093-66.644-64.243) -> 25.890585 | EZ3: =IF(BC3<>-999, BC3*$EY3, -999) -> 1.2641083e+08 | FA3: =IF(BD3<>-999, BD3*$EY3, -999) -> 18581739 | FB3: =IF(BE3<>-999, BE3*$EY3, -999) -> 1.4499256e+08 | FC3: =-29.317-(0.1023*G3)+H3*(100+102.093-66.644-64.243) -> 21.818585 | FD3: =IF(BF3<>-999,BF3*$FC3, -999) -> 53071304 | FE3: =IF(BG3<>-999,BG3*$FC3, -999) -> 7801207.8 | FF3: =IF(BH3<>-999,BH3*$FC3, -999) -> 60872512 | FG3: =-38.03-(0.1023*G3)+H3*(100+102.093-66.644-64.243) -> 13.105585 | FH3: =IF(BI3<>-999,BI3*$FG3, -999) -> 55306544 | FI3: =IF(BJ3<>-999,BJ3*$FG3, -999) -> 8129776.8 | FJ3: =IF(BK3<>-999,BK3*$FG3, -999) -> 63436321 | FK3: =EP3+ET3+EX3+FB3+FF3+FJ3 -> 6.4889502e+08 | FL3: =-17.17+0.435*(100+83.36-27.092-93.78) -> 10.01228 | FM3: =IF(AT3<>-999,AT3*$FL3, -999) -> 46445591 | FN3: =IF(AU3<>-999,AU3*$FL3, -999) -> 6827260.8 | FO3: =IF(AV3<>-999,AV3*$FL3, -999) -> 53272851 | FP3: =-19.943+0.435*(100+83.36-27.092-93.78) -> 7.23928 | FQ3: =IF(AW3<>-999,AW3*$FP3, -999) -> 16730066 | FR3: =IF(AX3<>-999,AX3*$FP3, -999) -> 2459232.9 | FS3: =IF(AY3<>-999,AY3*$FP3, -999) -> 19189299 | FT3: =-25.871+0.435*(100+83.36-27.092-93.78) -> 1.31128 | FU3: =IF(AZ3<>-999,AZ3*$FT3, -999) -> 5257564.8 | FV3: =IF(BA3<>-999,BA3*$FT3, -999) -> 772834.84 | FW3: =IF(BB3<>-999,BB3*$FT3, -999) -> 6030399.7 | FX3: =-25.245+0.435*(100+83.36-27.092-93.78) -> 1.93728 | FY3: =IF(BC3<>-999, BC3*$FX3, -999) -> 9458773.3 | FZ3: =IF(BD3<>-999, BD3*$FX3, -999) -> 1390390.8 | GA3: =IF(BE3<>-999, BE3*$FX3, -999) -> 10849164 | GB3: =-29.317+0.435*(100+83.36-27.092-93.78) -> -2.13472 | GC3: =IF(BF3<>-999,BF3*$GB3, -999) -> -5192471.2 | GD3: =IF(BG3<>-999,BG3*$GB3, -999) -> -763266.48 | GE3: =IF(BH3<>-999,BH3*$GB3, -999) -> -5955737.7 | GF3: =-38.03+0.435*(100+83.36-27.092-93.78) -> -10.84772 | GG3: =IF(BI3<>-999,BI3*$GF3, -999) -> -45778187 | GH3: =IF(BJ3<>-999,BJ3*$GF3, -999) -> -6729157.3 | GI3: =IF(BK3<>-999,BK3*$GF3, -999) -> -52507344 | GJ3: =FO3+FS3+FW3+GA3+GE3+GI3 -> 30878631
A4: California | B4: Calaveras | C4: 130 | D4: 0.995 | E4: 212.82786 | F4: 0.78156643 | G4: 55.152122 | H4: 0.81927917 | I4: 23812.7 | J4: 11102.2 | K4: =IF(J4<>-999, I4+J4, I4) -> 34914.9 | L4: 4390.9 | M4: 2047.2 | N4: =IF(M4<>-999, L4+M4, L4) -> 6438.1 | O4: 44836.6 | P4: 20904.1 | Q4: =IF(P4<>-999, O4+P4, O4) -> 65740.7 | R4: 13012.3 | S4: 6066.7 | T4: =IF(S4<>-999, R4+S4, R4) -> 19079 | U4: 2399.4 | V4: 1118.7 | W4: =IF(V4<>-999, U4+V4, U4) -> 3518.1 | X4: 24500.6 | Y4: 11422.9 | Z4: =IF(Y4<>-999, X4+Y4, X4) -> 35923.5 | AA4: 190204.5 | AB4: 59673.4 | AC4: 249878 | AD4: 35072.5 | AE4: 11003.4 | AF4: 46075.9 | AG4: 358133.5 | AH4: 112358.3 | AI4: 470491.9 | AJ4: 103935.9 | AK4: 32608.1 | AL4: 136544 | AM4: 19165.1 | AN4: 6012.7 | AO4: 25177.8 | AP4: 195699.4 | AQ4: 61397.4 | AR4: 257096.8 | AS4: 1185264.4 | AT4: =IF(AA4<>-999,AA4*0.5*3.67*0.907185, -999) -> 316630.48 | AU4: =IF(AB4<>-999,AB4*0.5*3.67*0.907185, -999) -> 99337.383 | AV4: =IF(AC4<>-999,AC4*0.5*3.67*0.907185, -999) -> 415968.03 | AW4: =IF(AD4<>-999,AD4*0.5*3.67*0.907185, -999) -> 58384.646 | AX4: =IF(AE4<>-999,AE4*0.5*3.67*0.907185, -999) -> 18317.189 | AY4: =IF(AF4<>-999,AF4*0.5*3.67*0.907185, -999) -> 76701.835 | AZ4: =IF(AG4<>-999,AG4*0.5*3.67*0.907185, -999) -> 596179.28 | BA4: =IF(AH4<>-999,AH4*0.5*3.67*0.907185, -999) -> 187041.12 | ... BL4: =IF(AS4<>-999,AS4*0.5*3.67*0.907185, -999) -> 1973091.2 | BM4: =-17.17-(0.1023*E4)+F4*(100-8.576-13.681) -> 21.819028 | BN4: =IF(AT4<>-999,AT4*$BM4, -999) -> 6908569.4 | BO4: =IF(AU4<>-999,AU4*$BM4, -999) -> 2167445.2 | BP4: =IF(AV4<>-999,AV4*$BM4, -999) -> 9076018.2 | BQ4: =-19.943-(0.1023*E4)+F4*(100-8.576-13.681) -> 19.046028 | BR4: =IF(AW4<>-999,AW4*$BQ4, -999) -> 1111995.6 | BS4: =IF(AX4<>-999,AX4*$BQ4, -999) -> 348869.7 | BT4: =IF(AY4<>-999,AY4*$BQ4, -999) -> 1460865.3 | BU4: =-25.871-(0.1023*E4)+F4*(100-8.576-13.681) -> 13.118028 | BV4: =IF(AZ4<>-999,AZ4*$BU4, -999) -> 7820696.7 | BW4: =IF(BA4<>-999,BA4*$BU4, -999) -> 2453610.7 | BX4: =IF(BB4<>-999,BB4*$BU4, -999) -> 10274310 | BY4: =-25.245-(0.1023*E4)+F4*(100-8.576-13.681) -> 13.744028 | BZ4: =IF(BC4<>-999,BC4*$BY4, -999) -> 2377998.4 | CA4: =IF(BD4<>-999,BD4*$BY4, -999) -> 746056.07 | CB4: =IF(BE4<>-999,BE4*$BY4, -999) -> 3124054.4 | CC4: =-29.317-(0.1023*E4)+F4*(100-8.576-13.681) -> 9.6720284 | CD4: =IF(BF4<>-999,BF4*$CC4, -999) -> 308574.89 | CE4: =IF(BG4<>-999,BG4*$CC4, -999) -> 96809.734 | CF4: =IF(BH4<>-999,BH4*$CC4, -999) -> 405384.62 | CG4: =-38.03-(0.1023*E4)+F4*(100-8.576-13.681) -> 0.95902836 | CH4: =IF(BI4<>-999,BI4*$CG4, -999) -> 312430.1 | CI4: =IF(BJ4<>-999,BJ4*$CG4, -999) -> 98019.698 | CJ4: =IF(BK4<>-999,BK4*$CG4, -999) -> 410449.8 | CK4: =BP4+BT4+BX4+CB4+CF4+CJ4 -> 24751082 | CL4: =((-55.825+0.1023*$E4)/$F4)+8.576+13.681 -> -21.312821 | CM4: =((-10.38+0.1023*$E4)/$F4)+8.576+13.681 -> 36.833228 | CN4: =((-100.485+0.1023*$E4)/$F4)+8.576+13.681 -> -78.454477 | CO4: =-17.17-22.91 -> -40.08 | CP4: =IF(AT4<>-999,AT4*$CO4, -999) -> -12690550 | CQ4: =IF(AU4<>-999,AU4*$CO4, -999) -> -3981442.3 | CR4: =IF(AV4<>-999,AV4*$CO4, -999) -> -16671999 | CS4: =-19.943-22.91 -> -42.853 | CT4: =IF(AW4<>-999,AW4*$CS4, -999) -> -2501957.2 | CU4: =IF(AX4<>-999,AX4*$CS4, -999) -> -784946.51 | CV4: =IF(AY4<>-999,AY4*$CS4, -999) -> -3286903.8 | CW4: =-25.871-22.91 -> -48.781 | CX4: =IF(AZ4<>-999,AZ4*$CO4, -999) -> -23894865 | CY4: =IF(BA4<>-999,BA4*$CO4, -999) -> -7496608 | CZ4: =IF(BB4<>-999,BB4*$CO4, -999) -> -31391480 | DA4: =-25.245-22.91 -> -48.155 | DB4: =IF(BC4<>-999,BC4*$DA4, -999) -> -8331801.2 | DC4: =IF(BD4<>-999,BD4*$DA4, -999) -> -2613959.2 | DD4: =IF(BE4<>-999,BE4*$DA4, -999) -> -10945760 | DE4: =-29.317-22.91 -> -52.227 | DF4: =IF(BF4<>-999,BF4*$DE4, -999) -> -1666242.1 | DG4: =IF(BG4<>-999,BG4*$DE4, -999) -> -522753.01 | DH4: =IF(BH4<>-999,BH4*$DE4, -999) -> -2188995.1 | DI4: =-38.03-22.91 -> -60.94 | DJ4: =IF(BI4<>-999,BI4*$DI4, -999) -> -19852896 | DK4: =IF(BJ4<>-999,BJ4*$DI4, -999) -> -6228512.8 | DL4: =IF(BK4<>-999,BK4*$DI4, -999) -> -26081409 | DM4: =CR4+CV4+CZ4+DD4+DH4+DL4 -> -90566547 | DN4: =-17.17 -> -17.17 | DO4: =IF(AT4<>-999,AT4*$DN4, -999) -> -5436545.3 | DP4: =IF(AU4<>-999,AU4*$DN4, -999) -> -1705622.9 | DQ4: =IF(AV4<>-999,AV4*$DN4, -999) -> -7142171 | DR4: =-19.943 -> -19.943 | DS4: =IF(AW4<>-999,AW4*$DR4, -999) -> -1164365 | DT4: =IF(AX4<>-999,AX4*$DR4, -999) -> -365299.7 | DU4: =IF(AY4<>-999,AY4*$DR4, -999) -> -1529664.7 | DV4: =-25.871 -> -25.871 | DW4: =IF(AZ4<>-999,AZ4*$DV4, -999) -> -15423754 | DX4: =IF(BA4<>-999,BA4*$DV4, -999) -> -4838940.8 | DY4: =IF(BB4<>-999,BB4*$DV4, -999) -> -20262699 | DZ4: =-25.245 -> -25.245 | EA4: =IF(BC4<>-999, BC4*$DZ4, -999) -> -4367902 | EB4: =IF(BD4<>-999, BD4*$DZ4, -999) -> -1370354.1 | EC4: =IF(BE4<>-999, BE4*$DZ4, -999) -> -5738256.1 | ED4: =-29.317 -> -29.317 | EE4: =IF(BF4<>-999,BF4*$ED4, -999) -> -935325.01 | EF4: =IF(BG4<>-999,BG4*$ED4, -999) -> -293441.13 | EG4: =IF(BH4<>-999,BH4*$ED4, -999) -> -1228766.1 | EH4: =-38.03 -> -38.03 | EI4: =IF(BI4<>-999,BI4*$EH4, -999) -> -12389328 | EJ4: =IF(BJ4<>-999,BJ4*$EH4, -999) -> -3886943.6 | EK4: =IF(BK4<>-999,BK4*$EH4, -999) -> -16276272 | EL4: =DQ4+DU4+DY4+EC4+EG4+EK4 -> -52177829 | EM4: =-17.17-(0.1023*G4)+H4*(100+102.093-66.644-64.243) -> 35.52553 | EN4: =IF(AT4<>-999,AT4*$EM4, -999) -> 11248466 | EO4: =IF(AU4<>-999,AU4*$EM4, -999) -> 3529013.2 | EP4: =IF(AV4<>-999,AV4*$EM4, -999) -> 14777485 | EQ4: =-19.943-(0.1023*G4)+H4*(100+102.093-66.644-64.243) -> 32.75253 | ER4: =IF(AW4<>-999,AW4*$EQ4, -999) -> 1912244.9 | ES4: =IF(AX4<>-999,AX4*$EQ4, -999) -> 599934.29 | ET4: =IF(AY4<>-999,AY4*$EQ4, -999) -> 2512179.2 | EU4: =-25.871-(0.1023*G4)+H4*(100+102.093-66.644-64.243) -> 26.82453 | EV4: =IF(AZ4<>-999,AZ4*$EU4, -999) -> 15992229 | EW4: =IF(BA4<>-999,BA4*$EU4, -999) -> 5017290.1 | EX4: =IF(BB4<>-999,BB4*$EU4, -999) -> 21009524 | EY4: =-25.245-(0.1023*G4)+H4*(100+102.093-66.644-64.243) -> 27.45053 | EZ4: =IF(BC4<>-999, BC4*$EY4, -999) -> 4749503.9 | FA4: =IF(BD4<>-999, BD4*$EY4, -999) -> 1490075.1 | FB4: =IF(BE4<>-999, BE4*$EY4, -999) -> 6239579 | FC4: =-29.317-(0.1023*G4)+H4*(100+102.093-66.644-64.243) -> 23.37853 | FD4: =IF(BF4<>-999,BF4*$FC4, -999) -> 745865 | FE4: =IF(BG4<>-999,BG4*$FC4, -999) -> 234001.52 | FF4: =IF(BH4<>-999,BH4*$FC4, -999) -> 979866.51 | FG4: =-38.03-(0.1023*G4)+H4*(100+102.093-66.644-64.243) -> 14.66553 | FH4: =IF(BI4<>-999,BI4*$FG4, -999) -> 4777703.5 | FI4: =IF(BJ4<>-999,BJ4*$FG4, -999) -> 1498924.2 | FJ4: =IF(BK4<>-999,BK4*$FG4, -999) -> 6276627.8 | FK4: =EP4+ET4+EX4+FB4+FF4+FJ4 -> 51795261 | FL4: =-17.17+0.435*(100+83.36-27.092-93.78) -> 10.01228 | FM4: =IF(AT4<>-999,AT4*$FL4, -999) -> 3170193 | FN4: =IF(AU4<>-999,AU4*$FL4, -999) -> 994593.69 | FO4: =IF(AV4<>-999,AV4*$FL4, -999) -> 4164788.4 | FP4: =-19.943+0.435*(100+83.36-27.092-93.78) -> 7.23928 | FQ4: =IF(AW4<>-999,AW4*$FP4, -999) -> 422662.8 | FR4: =IF(AX4<>-999,AX4*$FP4, -999) -> 132603.26 | FS4: =IF(AY4<>-999,AY4*$FP4, -999) -> 555266.06 | FT4: =-25.871+0.435*(100+83.36-27.092-93.78) -> 1.31128 | FU4: =IF(AZ4<>-999,AZ4*$FT4, -999) -> 781757.96 | FV4: =IF(BA4<>-999,BA4*$FT4, -999) -> 245263.28 | FW4: =IF(BB4<>-999,BB4*$FT4, -999) -> 1027021.5 | FX4: =-25.245+0.435*(100+83.36-27.092-93.78) -> 1.93728 | FY4: =IF(BC4<>-999, BC4*$FX4, -999) -> 335189.11 | FZ4: =IF(BD4<>-999, BD4*$FX4, -999) -> 105159.82 | GA4: =IF(BE4<>-999, BE4*$FX4, -999) -> 440348.93 | GB4: =-29.317+0.435*(100+83.36-27.092-93.78) -> -2.13472 | GC4: =IF(BF4<>-999,BF4*$GB4, -999) -> -68105.775 | GD4: =IF(BG4<>-999,BG4*$GB4, -999) -> -21366.943 | GE4: =IF(BH4<>-999,BH4*$GB4, -999) -> -89472.717 | GF4: =-38.03+0.435*(100+83.36-27.092-93.78) -> -10.84772 | GG4: =IF(BI4<>-999,BI4*$GF4, -999) -> -3533945.8 | GH4: =IF(BJ4<>-999,BJ4*$GF4, -999) -> -1108716.2 | GI4: =IF(BK4<>-999,BK4*$GF4, -999) -> -4642662 | GJ4: =FO4+FS4+FW4+GA4+GE4+GI4 -> 1455290.1
A5: California | B5: Tuolumne | C5: 146 | D5: 0.995 | E5: 242.06726 | F5: 0.78017396 | G5: 117.42988 | H5: 0.81487387 | I5: 12286.6 | J5: 24478.8 | K5: =IF(J5<>-999, I5+J5, I5) -> 36765.4 | L5: 3698.3 | M5: 7368.1 | N5: =IF(M5<>-999, L5+M5, L5) -> 11066.4 | O5: 14329.8 | P5: 28549.5 | Q5: =IF(P5<>-999, O5+P5, O5) -> 42879.3 | R5: 24730.1 | S5: 49270.1 | T5: =IF(S5<>-999, R5+S5, R5) -> 74000.2 | U5: 7443.8 | V5: 14830.3 | W5: =IF(V5<>-999, U5+V5, U5) -> 22274.1 | X5: 28842.6 | Y5: 57463.6 | Z5: =IF(Y5<>-999, X5+Y5, X5) -> 86306.2 | AA5: 117322.2 | AB5: 52698 | AC5: 170020.2 | AD5: 35314 | AE5: 15862.1 | AF5: 51176.1 | AG5: 136832.5 | AH5: 61461.5 | AI5: 198293.9 | AJ5: 236142.6 | AK5: 106068.9 | AL5: 342211.5 | AM5: 71079 | AN5: 31926.8 | AO5: 103005.8 | AP5: 275412.3 | AQ5: 123707.8 | AR5: 399120.1 | AS5: 1263827.6 | AT5: =IF(AA5<>-999,AA5*0.5*3.67*0.907185, -999) -> 195304.44 | AU5: =IF(AB5<>-999,AB5*0.5*3.67*0.907185, -999) -> 87725.542 | AV5: =IF(AC5<>-999,AC5*0.5*3.67*0.907185, -999) -> 283029.99 | AW5: =IF(AD5<>-999,AD5*0.5*3.67*0.907185, -999) -> 58786.668 | AX5: =IF(AE5<>-999,AE5*0.5*3.67*0.907185, -999) -> 26405.392 | AY5: =IF(AF5<>-999,AF5*0.5*3.67*0.907185, -999) -> 85192.059 | AZ5: =IF(AG5<>-999,AG5*0.5*3.67*0.907185, -999) -> 227782.94 | BA5: =IF(AH5<>-999,AH5*0.5*3.67*0.907185, -999) -> 102314 | ... BL5: =IF(AS5<>-999,AS5*0.5*3.67*0.907185, -999) -> 2103874.2 | BM5: =-17.17-(0.1023*E5)+F5*(100-8.576-13.681) -> 18.719584 | BN5: =IF(AT5<>-999,AT5*$BM5, -999) -> 3656017.9 | BO5: =IF(AU5<>-999,AU5*$BM5, -999) -> 1642185.7 | BP5: =IF(AV5<>-999,AV5*$BM5, -999) -> 5298203.6 | BQ5: =-19.943-(0.1023*E5)+F5*(100-8.576-13.681) -> 15.946584 | BR5: =IF(AW5<>-999,AW5*$BQ5, -999) -> 937446.53 | BS5: =IF(AX5<>-999,AX5*$BQ5, -999) -> 421075.79 | BT5: =IF(AY5<>-999,AY5*$BQ5, -999) -> 1358522.3 | BU5: =-25.871-(0.1023*E5)+F5*(100-8.576-13.681) -> 10.018584 | BV5: =IF(AZ5<>-999,AZ5*$BU5, -999) -> 2282062.5 | BW5: =IF(BA5<>-999,BA5*$BU5, -999) -> 1025041.4 | BX5: =IF(BB5<>-999,BB5*$BU5, -999) -> 3307102.3 | BY5: =-25.245-(0.1023*E5)+F5*(100-8.576-13.681) -> 10.644584 | BZ5: =IF(BC5<>-999,BC5*$BY5, -999) -> 4184417 | CA5: =IF(BD5<>-999,BD5*$BY5, -999) -> 1879527.5 | CB5: =IF(BE5<>-999,BE5*$BY5, -999) -> 6063944.5 | CC5: =-29.317-(0.1023*E5)+F5*(100-8.576-13.681) -> 6.5725839 | CD5: =IF(BF5<>-999,BF5*$CC5, -999) -> 777695.13 | CE5: =IF(BG5<>-999,BG5*$CC5, -999) -> 349320.01 | CF5: =IF(BH5<>-999,BH5*$CC5, -999) -> 1127015.1 | CG5: =-38.03-(0.1023*E5)+F5*(100-8.576-13.681) -> -2.1404161 | CH5: =IF(BI5<>-999,BI5*$CG5, -999) -> -981326.36 | CI5: =IF(BJ5<>-999,BJ5*$CG5, -999) -> -440785.41 | CJ5: =IF(BK5<>-999,BK5*$CG5, -999) -> -1422111.8 | CK5: =BP5+BT5+BX5+CB5+CF5+CJ5 -> 15732676 | CL5: =((-55.825+0.1023*$E5)/$F5)+8.576+13.681 -> -17.556582 | CM5: =((-10.38+0.1023*$E5)/$F5)+8.576+13.681 -> 40.693248 | CN5: =((-100.485+0.1023*$E5)/$F5)+8.576+13.681 -> -74.800225 | CO5: =-17.17-22.91 -> -40.08 | CP5: =IF(AT5<>-999,AT5*$CO5, -999) -> -7827802.2 | CQ5: =IF(AU5<>-999,AU5*$CO5, -999) -> -3516039.7 | CR5: =IF(AV5<>-999,AV5*$CO5, -999) -> -11343842 | CS5: =-19.943-22.91 -> -42.853 | CT5: =IF(AW5<>-999,AW5*$CS5, -999) -> -2519185.1 | CU5: =IF(AX5<>-999,AX5*$CS5, -999) -> -1131550.2 | CV5: =IF(AY5<>-999,AY5*$CS5, -999) -> -3650735.3 | CW5: =-25.871-22.91 -> -48.781 | CX5: =IF(AZ5<>-999,AZ5*$CO5, -999) -> -9129540.2 | CY5: =IF(BA5<>-999,BA5*$CO5, -999) -> -4100745.3 | CZ5: =IF(BB5<>-999,BB5*$CO5, -999) -> -13230279 | DA5: =-25.245-22.91 -> -48.155 | DB5: =IF(BC5<>-999,BC5*$DA5, -999) -> -18929871 | DC5: =IF(BD5<>-999,BD5*$DA5, -999) -> -8502788.6 | DD5: =IF(BE5<>-999,BE5*$DA5, -999) -> -27432660 | DE5: =-29.317-22.91 -> -52.227 | DF5: =IF(BF5<>-999,BF5*$DE5, -999) -> -6179713.2 | DG5: =IF(BG5<>-999,BG5*$DE5, -999) -> -2775763.1 | DH5: =IF(BH5<>-999,BH5*$DE5, -999) -> -8955476.3 | DI5: =-38.03-22.91 -> -60.94 | DJ5: =IF(BI5<>-999,BI5*$DI5, -999) -> -27939441 | DK5: =IF(BJ5<>-999,BJ5*$DI5, -999) -> -12549646 | DL5: =IF(BK5<>-999,BK5*$DI5, -999) -> -40489087 | DM5: =CR5+CV5+CZ5+DD5+DH5+DL5 -> -1.0510208e+08 | DN5: =-17.17 -> -17.17 | DO5: =IF(AT5<>-999,AT5*$DN5, -999) -> -3353377.3 | DP5: =IF(AU5<>-999,AU5*$DN5, -999) -> -1506247.6 | DQ5: =IF(AV5<>-999,AV5*$DN5, -999) -> -4859624.9 | DR5: =-19.943 -> -19.943 | DS5: =IF(AW5<>-999,AW5*$DR5, -999) -> -1172382.5 | DT5: =IF(AX5<>-999,AX5*$DR5, -999) -> -526602.72 | DU5: =IF(AY5<>-999,AY5*$DR5, -999) -> -1698985.2 | DV5: =-25.871 -> -25.871 | DW5: =IF(AZ5<>-999,AZ5*$DV5, -999) -> -5892972.4 | DX5: =IF(BA5<>-999,BA5*$DV5, -999) -> -2646965.6 | DY5: =IF(BB5<>-999,BB5*$DV5, -999) -> -8539933.7 | DZ5: =-25.245 -> -25.245 | EA5: =IF(BC5<>-999, BC5*$DZ5, -999) -> -9923883.2 | EB5: =IF(BD5<>-999, BD5*$DZ5, -999) -> -4457541.2 | EC5: =IF(BE5<>-999, BE5*$DZ5, -999) -> -14381424 | ED5: =-29.317 -> -29.317 | EE5: =IF(BF5<>-999,BF5*$ED5, -999) -> -3468907.9 | EF5: =IF(BG5<>-999,BG5*$ED5, -999) -> -1558141.3 | EG5: =IF(BH5<>-999,BH5*$ED5, -999) -> -5027049.2 | EH5: =-38.03 -> -38.03 | EI5: =IF(BI5<>-999,BI5*$EH5, -999) -> -17435788 | EJ5: =IF(BJ5<>-999,BJ5*$EH5, -999) -> -7831687.3 | EK5: =IF(BK5<>-999,BK5*$EH5, -999) -> -25267476 | EL5: =DQ5+DU5+DY5+EC5+EG5+EK5 -> -59774493 | EM5: =-17.17-(0.1023*G5)+H5*(100+102.093-66.644-64.243) -> 28.840832 | EN5: =IF(AT5<>-999,AT5*$EM5, -999) -> 5632742.6 | EO5: =IF(AU5<>-999,AU5*$EM5, -999) -> 2530077.6 | EP5: =IF(AV5<>-999,AV5*$EM5, -999) -> 8162820.2 | EQ5: =-19.943-(0.1023*G5)+H5*(100+102.093-66.644-64.243) -> 26.067832 | ER5: =IF(AW5<>-999,AW5*$EQ5, -999) -> 1532441 | ES5: =IF(AX5<>-999,AX5*$EQ5, -999) -> 688331.3 | ET5: =IF(AY5<>-999,AY5*$EQ5, -999) -> 2220772.3 | EU5: =-25.871-(0.1023*G5)+H5*(100+102.093-66.644-64.243) -> 20.139832 | EV5: =IF(AZ5<>-999,AZ5*$EU5, -999) -> 4587510 | EW5: =IF(BA5<>-999,BA5*$EU5, -999) -> 2060586.8 | EX5: =IF(BB5<>-999,BB5*$EU5, -999) -> 6648093.5 | EY5: =-25.245-(0.1023*G5)+H5*(100+102.093-66.644-64.243) -> 20.765832 | EZ5: =IF(BC5<>-999, BC5*$EY5, -999) -> 8163109.1 | FA5: =IF(BD5<>-999, BD5*$EY5, -999) -> 3666648.9 | FB5: =IF(BE5<>-999, BE5*$EY5, -999) -> 11829758 | FC5: =-29.317-(0.1023*G5)+H5*(100+102.093-66.644-64.243) -> 16.693832 | FD5: =IF(BF5<>-999,BF5*$FC5, -999) -> 1975282.7 | FE5: =IF(BG5<>-999,BG5*$FC5, -999) -> 887244.57 | FF5: =IF(BH5<>-999,BH5*$FC5, -999) -> 2862527.3 | FG5: =-38.03-(0.1023*G5)+H5*(100+102.093-66.644-64.243) -> 7.9808317 | FH5: =IF(BI5<>-999,BI5*$FG5, -999) -> 3659008.5 | FI5: =IF(BJ5<>-999,BJ5*$FG5, -999) -> 1643528.2 | FJ5: =IF(BK5<>-999,BK5*$FG5, -999) -> 5302536.7 | FK5: =EP5+ET5+EX5+FB5+FF5+FJ5 -> 37026508 | FL5: =-17.17+0.435*(100+83.36-27.092-93.78) -> 10.01228 | FM5: =IF(AT5<>-999,AT5*$FL5, -999) -> 1955442.8 | FN5: =IF(AU5<>-999,AU5*$FL5, -999) -> 878332.69 | FO5: =IF(AV5<>-999,AV5*$FL5, -999) -> 2833775.5 | FP5: =-19.943+0.435*(100+83.36-27.092-93.78) -> 7.23928 | FQ5: =IF(AW5<>-999,AW5*$FP5, -999) -> 425573.15 | FR5: =IF(AX5<>-999,AX5*$FP5, -999) -> 191156.02 | FS5: =IF(AY5<>-999,AY5*$FP5, -999) -> 616729.17 | FT5: =-25.871+0.435*(100+83.36-27.092-93.78) -> 1.31128 | FU5: =IF(AZ5<>-999,AZ5*$FT5, -999) -> 298687.21 | FV5: =IF(BA5<>-999,BA5*$FT5, -999) -> 134162.31 | FW5: =IF(BB5<>-999,BB5*$FT5, -999) -> 432849.3 | FX5: =-25.245+0.435*(100+83.36-27.092-93.78) -> 1.93728 | FY5: =IF(BC5<>-999, BC5*$FX5, -999) -> 761550.43 | FZ5: =IF(BD5<>-999, BD5*$FX5, -999) -> 342067.95 | GA5: =IF(BE5<>-999, BE5*$FX5, -999) -> 1103618.4 | GB5: =-29.317+0.435*(100+83.36-27.092-93.78) -> -2.13472 | GC5: =IF(BF5<>-999,BF5*$GB5, -999) -> -252588.84 | GD5: =IF(BG5<>-999,BG5*$GB5, -999) -> -113456.2 | GE5: =IF(BH5<>-999,BH5*$GB5, -999) -> -366045.04 | GF5: =-38.03+0.435*(100+83.36-27.092-93.78) -> -10.84772 | GG5: =IF(BI5<>-999,BI5*$GF5, -999) -> -4973403.9 | GH5: =IF(BJ5<>-999,BJ5*$GF5, -999) -> -2233919.3 | GI5: =IF(BK5<>-999,BK5*$GF5, -999) -> -7207323.2 | GJ5: =FO5+FS5+FW5+GA5+GE5+GI5 -> -2586395.9
A6: New Mexico | B6: Lincoln | C6: 42 | D6: 0.994 | E6: 106.94416 | F6: 0.79255077 | G6: 190.75651 | H6: 0.80920112 | I6: 36937.4 | J6: 4687.6 | K6: =IF(J6<>-999, I6+J6, I6) -> 41625 | L6: 22235.5 | M6: 2821.8 | N6: =IF(M6<>-999, L6+M6, L6) -> 25057.3 | O6: 26671 | P6: 3384.7 | Q6: =IF(P6<>-999, O6+P6, O6) -> 30055.7 | R6: 121239.4 | S6: 15386.1 | T6: =IF(S6<>-999, R6+S6, R6) -> 136625.5 | U6: 72983.5 | V6: 9262.1 | W6: =IF(V6<>-999, U6+V6, U6) -> 82245.6 | X6: 87542 | Y6: 11109.7 | Z6: =IF(Y6<>-999, X6+Y6, X6) -> 98651.7 | AA6: 408363 | AB6: 36522 | AC6: 444885 | AD6: 245825.8 | AE6: 21985.5 | AF6: 267811.2 | AG6: 294862.3 | AH6: 26371.1 | AI6: 321233.4 | AJ6: 1340368.6 | AK6: 119876.2 | AL6: 1460244.7 | AM6: 806873.1 | AN6: 72162.9 | AO6: 879036 | AP6: 967825.6 | AQ6: 86557.7 | AR6: 1054383.3 | AS6: 4427593.7 | AT6: =IF(AA6<>-999,AA6*0.5*3.67*0.907185, -999) -> 679795.55 | AU6: =IF(AB6<>-999,AB6*0.5*3.67*0.907185, -999) -> 60797.606 | AV6: =IF(AC6<>-999,AC6*0.5*3.67*0.907185, -999) -> 740593.15 | AW6: =IF(AD6<>-999,AD6*0.5*3.67*0.907185, -999) -> 409222.39 | AX6: =IF(AE6<>-999,AE6*0.5*3.67*0.907185, -999) -> 36598.921 | AY6: =IF(AF6<>-999,AF6*0.5*3.67*0.907185, -999) -> 445821.15 | AZ6: =IF(AG6<>-999,AG6*0.5*3.67*0.907185, -999) -> 490852.69 | BA6: =IF(AH6<>-999,AH6*0.5*3.67*0.907185, -999) -> 43899.561 | ... BL6: =IF(AS6<>-999,AS6*0.5*3.67*0.907185, -999) -> 7370546.5 | BM6: =-17.17-(0.1023*E6)+F6*(100-8.576-13.681) -> 33.504887 | BN6: =IF(AT6<>-999,AT6*$BM6, -999) -> 22776473 | BO6: =IF(AU6<>-999,AU6*$BM6, -999) -> 2037016.9 | BP6: =IF(AV6<>-999,AV6*$BM6, -999) -> 24813490 | BQ6: =-19.943-(0.1023*E6)+F6*(100-8.576-13.681) -> 30.731887 | BR6: =IF(AW6<>-999,AW6*$BQ6, -999) -> 12576176 | BS6: =IF(AX6<>-999,AX6*$BQ6, -999) -> 1124753.9 | BT6: =IF(AY6<>-999,AY6*$BQ6, -999) -> 13700925 | BU6: =-25.871-(0.1023*E6)+F6*(100-8.576-13.681) -> 24.803887 | BV6: =IF(AZ6<>-999,AZ6*$BU6, -999) -> 12175055 | BW6: =IF(BA6<>-999,BA6*$BU6, -999) -> 1088879.7 | BX6: =IF(BB6<>-999,BB6*$BU6, -999) -> 13263934 | BY6: =-25.245-(0.1023*E6)+F6*(100-8.576-13.681) -> 25.429887 | BZ6: =IF(BC6<>-999,BC6*$BY6, -999) -> 56741472 | CA6: =IF(BD6<>-999,BD6*$BY6, -999) -> 5074687.7 | CB6: =IF(BE6<>-999,BE6*$BY6, -999) -> 61816156 | CC6: =-29.317-(0.1023*E6)+F6*(100-8.576-13.681) -> 21.357887 | CD6: =IF(BF6<>-999,BF6*$CC6, -999) -> 28687681 | CE6: =IF(BG6<>-999,BG6*$CC6, -999) -> 2565690 | CF6: =IF(BH6<>-999,BH6*$CC6, -999) -> 31253371 | CG6: =-38.03-(0.1023*E6)+F6*(100-8.576-13.681) -> 12.644887 | CH6: =IF(BI6<>-999,BI6*$CG6, -999) -> 20372484 | CI6: =IF(BJ6<>-999,BJ6*$CG6, -999) -> 1822017.7 | CJ6: =IF(BK6<>-999,BK6*$CG6, -999) -> 22194501 | CK6: =BP6+BT6+BX6+CB6+CF6+CJ6 -> 1.6704238e+08 | CL6: =((-55.825+0.1023*$E6)/$F6)+8.576+13.681 -> -34.376107 | CM6: =((-10.38+0.1023*$E6)/$F6)+8.576+13.681 -> 22.964068 | CN6: =((-100.485+0.1023*$E6)/$F6)+8.576+13.681 -> -90.725809 | CO6: =-17.17-22.91 -> -40.08 | CP6: =IF(AT6<>-999,AT6*$CO6, -999) -> -27246205 | CQ6: =IF(AU6<>-999,AU6*$CO6, -999) -> -2436768.1 | CR6: =IF(AV6<>-999,AV6*$CO6, -999) -> -29682974 | CS6: =-19.943-22.91 -> -42.853 | CT6: =IF(AW6<>-999,AW6*$CS6, -999) -> -17536407 | CU6: =IF(AX6<>-999,AX6*$CS6, -999) -> -1568373.5 | CV6: =IF(AY6<>-999,AY6*$CS6, -999) -> -19104774 | CW6: =-25.871-22.91 -> -48.781 | CX6: =IF(AZ6<>-999,AZ6*$CO6, -999) -> -19673376 | CY6: =IF(BA6<>-999,BA6*$CO6, -999) -> -1759494.4 | CZ6: =IF(BB6<>-999,BB6*$CO6, -999) -> -21432870 | DA6: =-25.245-22.91 -> -48.155 | DB6: =IF(BC6<>-999,BC6*$DA6, -999) -> -1.0744781e+08 | DC6: =IF(BD6<>-999,BD6*$DA6, -999) -> -9609621.5 | DD6: =IF(BE6<>-999,BE6*$DA6, -999) -> -1.1705742e+08 | DE6: =-29.317-22.91 -> -52.227 | DF6: =IF(BF6<>-999,BF6*$DE6, -999) -> -70150738 | DG6: =IF(BG6<>-999,BG6*$DE6, -999) -> -6273949 | DH6: =IF(BH6<>-999,BH6*$DE6, -999) -> -76424687 | DI6: =-38.03-22.91 -> -60.94 | DJ6: =IF(BI6<>-999,BI6*$DI6, -999) -> -98181912 | DK6: =IF(BJ6<>-999,BJ6*$DI6, -999) -> -8780921.3 | DL6: =IF(BK6<>-999,BK6*$DI6, -999) -> -1.0696283e+08 | DM6: =CR6+CV6+CZ6+DD6+DH6+DL6 -> -3.7066556e+08 | DN6: =-17.17 -> -17.17 | DO6: =IF(AT6<>-999,AT6*$DN6, -999) -> -11672090 | DP6: =IF(AU6<>-999,AU6*$DN6, -999) -> -1043894.9 | DQ6: =IF(AV6<>-999,AV6*$DN6, -999) -> -12715984 | DR6: =-19.943 -> -19.943 | DS6: =IF(AW6<>-999,AW6*$DR6, -999) -> -8161122.2 | DT6: =IF(AX6<>-999,AX6*$DR6, -999) -> -729892.27 | DU6: =IF(AY6<>-999,AY6*$DR6, -999) -> -8891011.1 | DV6: =-25.871 -> -25.871 | DW6: =IF(AZ6<>-999,AZ6*$DV6, -999) -> -12698850 | DX6: =IF(BA6<>-999,BA6*$DV6, -999) -> -1135725.5 | DY6: =IF(BB6<>-999,BB6*$DV6, -999) -> -13834576 | DZ6: =-25.245 -> -25.245 | EA6: =IF(BC6<>-999, BC6*$DZ6, -999) -> -56328936 | EB6: =IF(BD6<>-999, BD6*$DZ6, -999) -> -5037792.5 | EC6: =IF(BE6<>-999, BE6*$DZ6, -999) -> -61366724 | ED6: =-29.317 -> -29.317 | EE6: =IF(BF6<>-999,BF6*$ED6, -999) -> -39378276 | EF6: =IF(BG6<>-999,BG6*$ED6, -999) -> -3521806 | EG6: =IF(BH6<>-999,BH6*$ED6, -999) -> -42900082 | EH6: =-38.03 -> -38.03 | EI6: =IF(BI6<>-999,BI6*$EH6, -999) -> -61271055 | EJ6: =IF(BJ6<>-999,BJ6*$EH6, -999) -> -5479790.6 | EK6: =IF(BK6<>-999,BK6*$EH6, -999) -> -66750846 | EL6: =DQ6+DU6+DY6+EC6+EG6+EK6 -> -2.0645922e+08 | EM6: =-17.17-(0.1023*G6)+H6*(100+102.093-66.644-64.243) -> 20.935584 | EN6: =IF(AT6<>-999,AT6*$EM6, -999) -> 14231917 | EO6: =IF(AU6<>-999,AU6*$EM6, -999) -> 1272833.4 | EP6: =IF(AV6<>-999,AV6*$EM6, -999) -> 15504750 | EQ6: =-19.943-(0.1023*G6)+H6*(100+102.093-66.644-64.243) -> 18.162584 | ER6: =IF(AW6<>-999,AW6*$EQ6, -999) -> 7432535.9 | ES6: =IF(AX6<>-999,AX6*$EQ6, -999) -> 664730.95 | ET6: =IF(AY6<>-999,AY6*$EQ6, -999) -> 8097263.9 | EU6: =-25.871-(0.1023*G6)+H6*(100+102.093-66.644-64.243) -> 12.234584 | EV6: =IF(AZ6<>-999,AZ6*$EU6, -999) -> 6005378.3 | EW6: =IF(BA6<>-999,BA6*$EU6, -999) -> 537092.85 | EX6: =IF(BB6<>-999,BB6*$EU6, -999) -> 6542471.2 | EY6: =-25.245-(0.1023*G6)+H6*(100+102.093-66.644-64.243) -> 12.860584 | EZ6: =IF(BC6<>-999, BC6*$EY6, -999) -> 28695702 | FA6: =IF(BD6<>-999, BD6*$EY6, -999) -> 2566407.3 | FB6: =IF(BE6<>-999, BE6*$EY6, -999) -> 31262107 | FC6: =-29.317-(0.1023*G6)+H6*(100+102.093-66.644-64.243) -> 8.7885836 | FD6: =IF(BF6<>-999,BF6*$FC6, -999) -> 11804730 | FE6: =IF(BG6<>-999,BG6*$FC6, -999) -> 1055759 | FF6: =IF(BH6<>-999,BH6*$FC6, -999) -> 12860489 | FG6: =-38.03-(0.1023*G6)+H6*(100+102.093-66.644-64.243) -> 0.075583616 | FH6: =IF(BI6<>-999,BI6*$FG6, -999) -> 121774.6 | FI6: =IF(BJ6<>-999,BJ6*$FG6, -999) -> 10890.938 | FJ6: =IF(BK6<>-999,BK6*$FG6, -999) -> 132665.54 | FK6: =EP6+ET6+EX6+FB6+FF6+FJ6 -> 74399746 | FL6: =-17.17+0.435*(100+83.36-27.092-93.78) -> 10.01228 | FM6: =IF(AT6<>-999,AT6*$FL6, -999) -> 6806303.4 | FN6: =IF(AU6<>-999,AU6*$FL6, -999) -> 608722.66 | FO6: =IF(AV6<>-999,AV6*$FL6, -999) -> 7415026 | FP6: =-19.943+0.435*(100+83.36-27.092-93.78) -> 7.23928 | FQ6: =IF(AW6<>-999,AW6*$FP6, -999) -> 2962475.5 | FR6: =IF(AX6<>-999,AX6*$FP6, -999) -> 264949.83 | FS6: =IF(AY6<>-999,AY6*$FP6, -999) -> 3227424.1 | FT6: =-25.871+0.435*(100+83.36-27.092-93.78) -> 1.31128 | FU6: =IF(AZ6<>-999,AZ6*$FT6, -999) -> 643645.32 | FV6: =IF(BA6<>-999,BA6*$FT6, -999) -> 57564.616 | FW6: =IF(BB6<>-999,BB6*$FT6, -999) -> 701209.94 | FX6: =-25.245+0.435*(100+83.36-27.092-93.78) -> 1.93728 | FY6: =IF(BC6<>-999, BC6*$FX6, -999) -> 4322635 | FZ6: =IF(BD6<>-999, BD6*$FX6, -999) -> 386595.94 | GA6: =IF(BE6<>-999, BE6*$FX6, -999) -> 4709230.7 | GB6: =-29.317+0.435*(100+83.36-27.092-93.78) -> -2.13472 | GC6: =IF(BF6<>-999,BF6*$GB6, -999) -> -2867332.7 | GD6: =IF(BG6<>-999,BG6*$GB6, -999) -> -256440.62 | GE6: =IF(BH6<>-999,BH6*$GB6, -999) -> -3123773.3 | GF6: =-38.03+0.435*(100+83.36-27.092-93.78) -> -10.84772 | GG6: =IF(BI6<>-999,BI6*$GF6, -999) -> -17477025 | GH6: =IF(BJ6<>-999,BJ6*$GF6, -999) -> -1563061.6 | GI6: =IF(BK6<>-999,BK6*$GF6, -999) -> -19040086 | GJ6: =FO6+FS6+FW6+GA6+GE6+GI6 -> -6110969
A7: California | B7: Amador | C7: 89 | D7: 0.994 | E7: 206.44376 | F7: 0.78203523 | G7: 64.585432 | H7: 0.81896261 | I7: 14647.5 | J7: 31448.6 | K7: =IF(J7<>-999, I7+J7, I7) -> 46096.1 | L7: 9593.1 | M7: 20596.7 | N7: =IF(M7<>-999, L7+M7, L7) -> 30189.8 | O7: 27897.2 | P7: 59896.1 | Q7: =IF(P7<>-999, O7+P7, O7) -> 87793.3 | R7: 17824.9 | S7: 38270.6 | T7: =IF(S7<>-999, R7+S7, R7) -> 56095.5 | U7: 11674.2 | V7: 25064.7 | W7: =IF(V7<>-999, U7+V7, U7) -> 36738.9 | X7: 33948.9 | Y7: 72889.1 | Z7: =IF(Y7<>-999, X7+Y7, X7) -> 106838 | AA7: 750181.7 | AB7: 828998.2 | AC7: 1579179.9 | AD7: 491319.4 | AE7: 542939 | AF7: 1034258.4 | AG7: 1428774.9 | AH7: 1578886.6 | AI7: 3007661.5 | AJ7: 912915.7 | AK7: 1008829.6 | AL7: 1921745.3 | AM7: 597899.4 | AN7: 660716.7 | AO7: 1258616.2 | AP7: 1738713.6 | AQ7: 1921388.5 | AR7: 3660102 | AS7: 12461563 | AT7: =IF(AA7<>-999,AA7*0.5*3.67*0.907185, -999) -> 1248815.8 | AU7: =IF(AB7<>-999,AB7*0.5*3.67*0.907185, -999) -> 1380020.4 | AV7: =IF(AC7<>-999,AC7*0.5*3.67*0.907185, -999) -> 2628836.3 | AW7: =IF(AD7<>-999,AD7*0.5*3.67*0.907185, -999) -> 817891.78 | AX7: =IF(AE7<>-999,AE7*0.5*3.67*0.907185, -999) -> 903822.12 | AY7: =IF(AF7<>-999,AF7*0.5*3.67*0.907185, -999) -> 1721713.9 | AZ7: =IF(AG7<>-999,AG7*0.5*3.67*0.907185, -999) -> 2378459.4 | BA7: =IF(AH7<>-999,AH7*0.5*3.67*0.907185, -999) -> 2628348 | ... BL7: =IF(AS7<>-999,AS7*0.5*3.67*0.907185, -999) -> 20744571 | BM7: =-17.17-(0.1023*E7)+F7*(100-8.576-13.681) -> 22.508568 | BN7: =IF(AT7<>-999,AT7*$BM7, -999) -> 28109057 | BO7: =IF(AU7<>-999,AU7*$BM7, -999) -> 31062284 | BP7: =IF(AV7<>-999,AV7*$BM7, -999) -> 59171341 | BQ7: =-19.943-(0.1023*E7)+F7*(100-8.576-13.681) -> 19.735568 | BR7: =IF(AW7<>-999,AW7*$BQ7, -999) -> 16141559 | BS7: =IF(AX7<>-999,AX7*$BQ7, -999) -> 17837443 | BT7: =IF(AY7<>-999,AY7*$BQ7, -999) -> 33979003 | BU7: =-25.871-(0.1023*E7)+F7*(100-8.576-13.681) -> 13.807568 | BV7: =IF(AZ7<>-999,AZ7*$BU7, -999) -> 32840741 | BW7: =IF(BA7<>-999,BA7*$BU7, -999) -> 36291095 | BX7: =IF(BB7<>-999,BB7*$BU7, -999) -> 69131836 | BY7: =-25.245-(0.1023*E7)+F7*(100-8.576-13.681) -> 14.433568 | BZ7: =IF(BC7<>-999,BC7*$BY7, -999) -> 21934933 | CA7: =IF(BD7<>-999,BD7*$BY7, -999) -> 24239489 | CB7: =IF(BE7<>-999,BE7*$BY7, -999) -> 46174423 | CC7: =-29.317-(0.1023*E7)+F7*(100-8.576-13.681) -> 10.361568 | CD7: =IF(BF7<>-999,BF7*$CC7, -999) -> 10313013 | CE7: =IF(BG7<>-999,BG7*$CC7, -999) -> 11396532 | CF7: =IF(BH7<>-999,BH7*$CC7, -999) -> 21709546 | CG7: =-38.03-(0.1023*E7)+F7*(100-8.576-13.681) -> 1.6485684 | CH7: =IF(BI7<>-999,BI7*$CG7, -999) -> 4771632.2 | CI7: =IF(BJ7<>-999,BJ7*$CG7, -999) -> 5272955.4 | CJ7: =IF(BK7<>-999,BK7*$CG7, -999) -> 10044587 | CK7: =BP7+BT7+BX7+CB7+CF7+CJ7 -> 2.4021074e+08 | CL7: =((-55.825+0.1023*$E7)/$F7)+8.576+13.681 -> -22.121823 | CM7: =((-10.38+0.1023*$E7)/$F7)+8.576+13.681 -> 35.989369 | CN7: =((-100.485+0.1023*$E7)/$F7)+8.576+13.681 -> -79.229225 | CO7: =-17.17-22.91 -> -40.08 | CP7: =IF(AT7<>-999,AT7*$CO7, -999) -> -50052538 | CQ7: =IF(AU7<>-999,AU7*$CO7, -999) -> -55311219 | CR7: =IF(AV7<>-999,AV7*$CO7, -999) -> -1.0536376e+08 | CS7: =-19.943-22.91 -> -42.853 | CT7: =IF(AW7<>-999,AW7*$CS7, -999) -> -35049116 | CU7: =IF(AX7<>-999,AX7*$CS7, -999) -> -38731489 | CV7: =IF(AY7<>-999,AY7*$CS7, -999) -> -73780606 | CW7: =-25.871-22.91 -> -48.781 | CX7: =IF(AZ7<>-999,AZ7*$CO7, -999) -> -95328653 | CY7: =IF(BA7<>-999,BA7*$CO7, -999) -> -1.0534419e+08 | CZ7: =IF(BB7<>-999,BB7*$CO7, -999) -> -2.0067284e+08 | DA7: =-25.245-22.91 -> -48.155 | DB7: =IF(BC7<>-999,BC7*$DA7, -999) -> -73181953 | DC7: =IF(BD7<>-999,BD7*$DA7, -999) -> -80870687 | DD7: =IF(BE7<>-999,BE7*$DA7, -999) -> -1.5405264e+08 | DE7: =-29.317-22.91 -> -52.227 | DF7: =IF(BF7<>-999,BF7*$DE7, -999) -> -51982256 | DG7: =IF(BG7<>-999,BG7*$DE7, -999) -> -57443685 | DH7: =IF(BH7<>-999,BH7*$DE7, -999) -> -1.0942595e+08 | DI7: =-38.03-22.91 -> -60.94 | DJ7: =IF(BI7<>-999,BI7*$DI7, -999) -> -1.7638532e+08 | DK7: =IF(BJ7<>-999,BJ7*$DI7, -999) -> -1.9491693e+08 | DL7: =IF(BK7<>-999,BK7*$DI7, -999) -> -3.7130224e+08 | DM7: =CR7+CV7+CZ7+DD7+DH7+DL7 -> -1.014598e+09 | DN7: =-17.17 -> -17.17 | DO7: =IF(AT7<>-999,AT7*$DN7, -999) -> -21442168 | DP7: =IF(AU7<>-999,AU7*$DN7, -999) -> -23694951 | DQ7: =IF(AV7<>-999,AV7*$DN7, -999) -> -45137119 | DR7: =-19.943 -> -19.943 | DS7: =IF(AW7<>-999,AW7*$DR7, -999) -> -16311216 | DT7: =IF(AX7<>-999,AX7*$DR7, -999) -> -18024925 | DU7: =IF(AY7<>-999,AY7*$DR7, -999) -> -34336140 | DV7: =-25.871 -> -25.871 | DW7: =IF(AZ7<>-999,AZ7*$DV7, -999) -> -61533123 | DX7: =IF(BA7<>-999,BA7*$DV7, -999) -> -67997991 | DY7: =IF(BB7<>-999,BB7*$DV7, -999) -> -1.2953111e+08 | DZ7: =-25.245 -> -25.245 | EA7: =IF(BC7<>-999, BC7*$DZ7, -999) -> -38365245 | EB7: =IF(BD7<>-999, BD7*$DZ7, -999) -> -42396023 | EC7: =IF(BE7<>-999, BE7*$DZ7, -999) -> -80761269 | ED7: =-29.317 -> -29.317 | EE7: =IF(BF7<>-999,BF7*$ED7, -999) -> -29179616 | EF7: =IF(BG7<>-999,BG7*$ED7, -999) -> -32245324 | EG7: =IF(BH7<>-999,BH7*$ED7, -999) -> -61424945 | EH7: =-38.03 -> -38.03 | EI7: =IF(BI7<>-999,BI7*$EH7, -999) -> -1.1007439e+08 | EJ7: =IF(BJ7<>-999,BJ7*$EH7, -999) -> -1.2163917e+08 | EK7: =IF(BK7<>-999,BK7*$EH7, -999) -> -2.3171356e+08 | EL7: =DQ7+DU7+DY7+EC7+EG7+EK7 -> -5.8290414e+08 | EM7: =-17.17-(0.1023*G7)+H7*(100+102.093-66.644-64.243) -> 34.537962 | EN7: =IF(AT7<>-999,AT7*$EM7, -999) -> 43131554 | EO7: =IF(AU7<>-999,AU7*$EM7, -999) -> 47663093 | EP7: =IF(AV7<>-999,AV7*$EM7, -999) -> 90794647 | EQ7: =-19.943-(0.1023*G7)+H7*(100+102.093-66.644-64.243) -> 31.764962 | ER7: =IF(AW7<>-999,AW7*$EQ7, -999) -> 25980301 | ES7: =IF(AX7<>-999,AX7*$EQ7, -999) -> 28709875 | ET7: =IF(AY7<>-999,AY7*$EQ7, -999) -> 54690176 | EU7: =-25.871-(0.1023*G7)+H7*(100+102.093-66.644-64.243) -> 25.836962 | EV7: =IF(AZ7<>-999,AZ7*$EU7, -999) -> 61452165 | EW7: =IF(BA7<>-999,BA7*$EU7, -999) -> 67908527 | EX7: =IF(BB7<>-999,BB7*$EU7, -999) -> 1.2936069e+08 | EY7: =-25.245-(0.1023*G7)+H7*(100+102.093-66.644-64.243) -> 26.462962 | EZ7: =IF(BC7<>-999, BC7*$EY7, -999) -> 40216202 | FA7: =IF(BD7<>-999, BD7*$EY7, -999) -> 44441448 | FB7: =IF(BE7<>-999, BE7*$EY7, -999) -> 84657650 | FC7: =-29.317-(0.1023*G7)+H7*(100+102.093-66.644-64.243) -> 22.390962 | FD7: =IF(BF7<>-999,BF7*$FC7, -999) -> 22286034 | FE7: =IF(BG7<>-999,BG7*$FC7, -999) -> 24627479 | FF7: =IF(BH7<>-999,BH7*$FC7, -999) -> 46913518 | FG7: =-38.03-(0.1023*G7)+H7*(100+102.093-66.644-64.243) -> 13.677962 | FH7: =IF(BI7<>-999,BI7*$FG7, -999) -> 39589623 | FI7: =IF(BJ7<>-999,BJ7*$FG7, -999) -> 43749038 | FJ7: =IF(BK7<>-999,BK7*$FG7, -999) -> 83338659 | FK7: =EP7+ET7+EX7+FB7+FF7+FJ7 -> 4.8975534e+08 | FL7: =-17.17+0.435*(100+83.36-27.092-93.78) -> 10.01228 | FM7: =IF(AT7<>-999,AT7*$FL7, -999) -> 12503494 | FN7: =IF(AU7<>-999,AU7*$FL7, -999) -> 13817151 | FO7: =IF(AV7<>-999,AV7*$FL7, -999) -> 26320645 | FP7: =-19.943+0.435*(100+83.36-27.092-93.78) -> 7.23928 | FQ7: =IF(AW7<>-999,AW7*$FP7, -999) -> 5920947.6 | FR7: =IF(AX7<>-999,AX7*$FP7, -999) -> 6543021.4 | FS7: =IF(AY7<>-999,AY7*$FP7, -999) -> 12463969 | FT7: =-25.871+0.435*(100+83.36-27.092-93.78) -> 1.31128 | FU7: =IF(AZ7<>-999,AZ7*$FT7, -999) -> 3118826.2 | FV7: =IF(BA7<>-999,BA7*$FT7, -999) -> 3446500.2 | FW7: =IF(BB7<>-999,BB7*$FT7, -999) -> 6565326.4 | FX7: =-25.245+0.435*(100+83.36-27.092-93.78) -> 1.93728 | FY7: =IF(BC7<>-999, BC7*$FX7, -999) -> 2944116.6 | FZ7: =IF(BD7<>-999, BD7*$FX7, -999) -> 3253435 | GA7: =IF(BE7<>-999, BE7*$FX7, -999) -> 6197551.6 | GB7: =-29.317+0.435*(100+83.36-27.092-93.78) -> -2.13472 | GC7: =IF(BF7<>-999,BF7*$GB7, -999) -> -2124716.4 | GD7: =IF(BG7<>-999,BG7*$GB7, -999) -> -2347946.2 | GE7: =IF(BH7<>-999,BH7*$GB7, -999) -> -4472662.9 | GF7: =-38.03+0.435*(100+83.36-27.092-93.78) -> -10.84772 | GG7: =IF(BI7<>-999,BI7*$GF7, -999) -> -31397744 | GH7: =IF(BJ7<>-999,BJ7*$GF7, -999) -> -34696493 | GI7: =IF(BK7<>-999,BK7*$GF7, -999) -> -66094236 | GJ7: =FO7+FS7+FW7+GA7+GE7+GI7 -> -19019407
